Workbook

Sheet Comparison
A3: BAR | B3: BAR Sum of Net Invoice Amount | C3: AOS Pre Export | D3: Diff
A4: 250528 | B4: 0 | C4: =VLOOKUP(A4,'AOS Pivot'!A:B,2,FALSE) -> 0 | D4: =(B4-C4) -> 0
A5: 251886 | B5: 6741.12 | C5: =VLOOKUP(A5,'AOS Pivot'!A:B,2,FALSE) -> 6741.12 | D5: =(B5-C5) -> 9.094947e-13
A6: 252135 | B6: 0 | C6: =VLOOKUP(A6,'AOS Pivot'!A:B,2,FALSE) -> 0 | D6: =(B6-C6) -> 0
A7: 252314 | B7: 0 | C7: =VLOOKUP(A7,'AOS Pivot'!A:B,2,FALSE) -> 0 | D7: =(B7-C7) -> 0
A8: 252340 | B8: 30427.14 | C8: =VLOOKUP(A8,'AOS Pivot'!A:B,2,FALSE) -> 30427.135 | D8: =(B8-C8) -> 0.005
A9: 252732 | B9: 55223.11 | C9: =VLOOKUP(A9,'AOS Pivot'!A:B,2,FALSE) -> 55218.55 | D9: =(B9-C9) -> 4.56
A10: 252733 | B10: 30355.25 | C10: =VLOOKUP(A10,'AOS Pivot'!A:B,2,FALSE) -> 30351.205 | D10: =(B10-C10) -> 4.045
A11: 252736 | B11: 40743.07 | C11: =VLOOKUP(A11,'AOS Pivot'!A:B,2,FALSE) -> 40738.018 | D11: =(B11-C11) -> 5.052
A12: 253348 | B12: 7190.04 | C12: =VLOOKUP(A12,'AOS Pivot'!A:B,2,FALSE) -> 7189.9211 | D12: =(B12-C12) -> 0.1189
A13: 253612 | B13: 0 | C13: =VLOOKUP(A13,'AOS Pivot'!A:B,2,FALSE) -> 0 | D13: =(B13-C13) -> 0
A14: 254371 | B14: 965.55 | C14: =VLOOKUP(A14,'AOS Pivot'!A:B,2,FALSE) -> 8689.4958 | D14: =(B14-C14) -> -7723.9458
A15: 256852 | B15: 165693.24 | C15: =VLOOKUP(A15,'AOS Pivot'!A:B,2,FALSE) -> 331386.48 | D15: =(B15-C15) -> -165693.24
... A214: 272533 | B214: 6409.48 | C214: =VLOOKUP(A214,'AOS Pivot'!A:B,2,FALSE) -> 12818.96 | D214: =(B214-C214) -> -6409.48
A215: Grand Total | B215: 29131400 | C215: =VLOOKUP(A215,'AOS Pivot'!A:B,2,FALSE) -> 56204191 | D215: =(B215-C215) -> -27072791

Sheet BAR Pivot
A3: BAR | B3: BAR Sum of Net Invoice Amount
A4: 250528 | B4: 0
A5: 251886 | B5: 6741.12
A6: 252135 | B6: 0
A7: 252314 | B7: 0
A8: 252340 | B8: 30427.14
A9: 252732 | B9: 55223.11
A10: 252733 | B10: 30355.25
A11: 252736 | B11: 40743.07
A12: 253348 | B12: 7190.04
A13: 253612 | B13: 0
A14: 254371 | B14: 965.55
A15: 256852 | B15: 165693.24
... A214: 272533 | B214: 6409.48
A215: Grand Total | B215: 29131400

Sheet Cash BAR
A1: Agency | B1: Agency ID | C1: Advertiser ID | D1: Advertiser | E1: Sales Order | F1: Sales Order ID | G1: Parent Line Item | H1: Parent Line Item ID | I1: Sales Line Item | J1: PS Line Item ID | K1: Placement Property | L1: Cost Method | M1: Net Unit Cost | N1: Billable Metric | O1: Billable Impressions | P1: Billable Revenue | Q1: Price | R1: Revised Billed Impressions | S1: Revised Billed Revenue | T1: Parent Line Item Revenue | U1: Reason for Revision | V1: Special Billing Instructions | W1: 1P Imps | X1: 3P Imps | Y1: 1P Demo Imps | Z1: 3P Demo Imps | AA1: Viewability | AB1: Demo Comp | AC1: Equivalization Factor | AD1: Equivalized Imps | AE1: Billing Scenario | AF1: Net Invoice Amount | AG1: Quantity | AH1: Net Cost | AI1: Campaign | AJ1: Campaign ID | AK1: Demo Band | AL1: External PO Ref | AM1: Sales Region | AN1: Primary Salesperson | AO1: Sales Line Item Type | AP1: Product | AQ1: Invoice ID | AR1: Billing Period End Date | AS1: Parent Line Item Start Date | AT1: Parent Line Item End Date | AU1: Product Category | AV1: Previously Billed | AW1: Report Date
A2: A24 FILMS | B2: 20096 | C2: 12011 | D2: A24 FILMS | E2: A24 Death of Robin Hood/Digital/Scatter/AllFOX & Abs A/25.26/2Q26 | F2: 262385 | G2: DIO - ROV - 1F SEN - Pre/Mid - ROS - FW - SXD - Package (AAT A25-54 and Fandango Fans) | H2: 565285 | I2: DIO - LFV - 1F - Tubi - Pre/Mid - ROS - DT/MB/CTV - FW - SXD (AAT A25-54 and Fandango Fans) | J2: 94341364 | K2: Fox Sold Tubi | L2: CPM | M2: 21.25 | N2: 1P Audience Target | O2: 4071061 | P2: 84000 | S2: =IF(ISBLANK(R2)," ",ROUND(R2*(IF(ISBLANK(Q2),(M2/1000),(Q2/1000))),2)) | T2: =IF(IF(COUNTIF(H$2:$H2,H2)=1,1,"")=1,SUMIF($H$2:$H$7997,H2,$S$2:$S$7997),"") -> 0 | W2: 4071061 | X2: 4071061 | Y2: 0 | Z2: 0 | AA2: 1 | AB2: 0 | AC2: 0 | AD2: 0 | AE2: Bill on Actuals - 3rd Party Performance | AF2: 42000 | AG2: 3952941 | AH2: 84000 | AI2: A24 Death of Robin Hood/Digital/Scatter/AllFOX & Abs A/25.26/2Q26 | AJ2: 94341361 | AK2: Audience Target | AL2: n/a | AN2: Kimberly Caraig | AO2: Guaranteed | AP2: DIO - LFV - 1F - Tubi - Pre/Mid - ROS - DT/MB/CTV - FW - SXD | AQ2: 129821 | AR2: 46203 | AS2: 46174 | AT2: 46201 | AU2: Direct LFV | AW2: 46208.537
A3: A24 FILMS | B3: 20096 | C3: 12011 | D3: A24 FILMS | E3: A24 Death of Robin Hood/Digital/Scatter/AllFOX & Abs A/25.26/2Q26 | F3: 262385 | G3: DIO - ROV - 1F SEN - Pre/Mid - ROS - FW - SXD - Package (AAT A25-54 and Fandango Fans) | H3: 565285 | I3: DIO - ROV - 1F - SEN - Pre/Mid - ROS - DT/MB/CTV - SXD (AAT A25-54 and Fandango Fans) | J3: 94341367 | K3: OneFOX | L3: CPM | M3: 21.25 | N3: 1P Audience Target | O3: 6037472 | P3: 126000.01 | S3: =IF(ISBLANK(R3)," ",ROUND(R3*(IF(ISBLANK(Q3),(M3/1000),(Q3/1000))),2)) | T3: =IF(IF(COUNTIF(H$2:$H3,H3)=1,1,"")=1,SUMIF($H$2:$H$7997,H3,$S$2:$S$7997),"") | W3: 6037472 | X3: 6037472 | Y3: 0 | Z3: 0 | AA3: 1 | AB3: 0 | AC3: 0 | AD3: 0 | AE3: Bill on Actuals - 3rd Party Performance | AF3: 63000.01 | AG3: 5929412 | AH3: 126000.01 | AI3: A24 Death of Robin Hood/Digital/Scatter/AllFOX & Abs A/25.26/2Q26 | AJ3: 94341361 | AK3: Audience Target | AL3: n/a | AN3: Kimberly Caraig | AO3: Guaranteed | AP3: DIO - ROV - 1F - SEN - Pre/Mid - ROS - DT/MB/CTV - SXD | AQ3: 129821 | AR3: 46203 | AS3: 46174 | AT3: 46201 | AU3: Direct ROV | AW3: 46208.537
A4: A24 FILMS | B4: 20096 | C4: 12011 | D4: A24 FILMS | E4: A24 Death of Robin Hood/Digital/Scatter/AllFOX & Abs A/25.26/2Q26 | F4: 262385 | G4: DIO - LFV - RON Ent - Absolute A - Show Mix - DT/MB/CTV/STB (Masked Singer and Fear Factor) | H4: 565482 | I4: DIO - LFV - RON Ent - Absolute A - Show Mix - DT/MB/CTV/STB (Masked Singer and Fear Factor) | J4: 94341371 | K4: RON - Ent | L4: CPM | M4: 30 | N4: Absolute A | O4: 1359729 | P4: 40000.02 | S4: =IF(ISBLANK(R4)," ",ROUND(R4*(IF(ISBLANK(Q4),(M4/1000),(Q4/1000))),2)) | T4: =IF(IF(COUNTIF(H$2:$H4,H4)=1,1,"")=1,SUMIF($H$2:$H$7997,H4,$S$2:$S$7997),"") -> 0 | W4: 1133108 | X4: 1133108 | Y4: 1359729 | Z4: 1359729 | AA4: 1 | AB4: 1.2 | AC4: 0 | AD4: 0 | AE4: Bill on Actuals - 3rd Party Performance | AF4: 33993.24 | AG4: 1333334 | AH4: 40000.02 | AI4: A24 Death of Robin Hood/Digital/Scatter/AllFOX & Abs A/25.26/2Q26 | AJ4: 94341361 | AK4: P2+ | AL4: n/a | AN4: Kimberly Caraig | AO4: Guaranteed | AP4: DIO - LFV - RON Ent - Absolute A - Show Mix - DT/MB/CTV/STB | AQ4: 129821 | AR4: 46203 | AS4: 46174 | AT4: 46201 | AU4: Direct LFV | AW4: 46208.537
A5: ADVERTISING COUNCIL | B5: 11885 | C5: 1148 | D5: ADVERTISING COUNCIL | E5: Ad Council/2025/Dig/Pro-bono/2Q26/OneFox | F5: 265136 | G5: Ad Council - LFV - 1F - Pre/Mid - ROS - FW - SXD - Package- 2Q'26 - Pro-Bono | H5: 574526 | I5: Ad Council - DIO - ROV - 1F - SEN - Pre/Mid - ROS - DT/MB/CTV - SXD - 2Q'26 | J5: 92762829 | K5: OneFOX | L5: CPM | M5: 25 | N5: 3P Imps | O5: 1043604 | P5: 0 | S5: =IF(ISBLANK(R5)," ",ROUND(R5*(IF(ISBLANK(Q5),(M5/1000),(Q5/1000))),2)) | T5: =IF(IF(COUNTIF(H$2:$H5,H5)=1,1,"")=1,SUMIF($H$2:$H$7997,H5,$S$2:$S$7997),"") -> 0 | W5: 737435 | X5: 1043604 | Y5: 0 | Z5: 0 | AA5: 1 | AB5: 0 | AC5: 0 | AD5: 0 | AE5: Bill on Actuals - 3rd Party Performance | AF5: 0 | AG5: 3000000 | AH5: 0 | AI5: Ad Council/2025/Dig/Pro-bono/2Q26/OneFox | AJ5: 92762823 | AK5: P2+ | AN5: Nicholas Vara | AO5: Guaranteed | AP5: DIO - ROV - 1F - SEN - Pre/Mid - ROS - DT/MB/CTV - SXD | AQ5: 121448 | AR5: 46203 | AS5: 46113 | AT5: 46203 | AU5: Direct ROV | AW5: 46208.537
A6: ADVERTISING COUNCIL | B6: 11885 | C6: 1148 | D6: ADVERTISING COUNCIL | E6: Ad Council/2025/Dig/Pro-bono/2Q26/OneFox | F6: 265136 | G6: Ad Council - LFV - 1F - Pre/Mid - ROS - FW - SXD - Package- 2Q'26 - Pro-Bono | H6: 574526 | I6: Ad Council - LFV - 1F - Tubi - Pre/Mid - ROS - DT/MB/CTV - FW - SXD - 2Q'26 | J6: 92762826 | K6: Fox Sold Tubi | L6: CPM | M6: 25 | N6: 3P Imps | O6: 1017750 | P6: 0 | S6: =IF(ISBLANK(R6)," ",ROUND(R6*(IF(ISBLANK(Q6),(M6/1000),(Q6/1000))),2)) | T6: =IF(IF(COUNTIF(H$2:$H6,H6)=1,1,"")=1,SUMIF($H$2:$H$7997,H6,$S$2:$S$7997),"") | W6: 741825 | X6: 1017750 | Y6: 0 | Z6: 0 | AA6: 1 | AB6: 0 | AC6: 0 | AD6: 0 | AE6: Bill on Actuals - 3rd Party Performance | AF6: 0 | AG6: 3000000 | AH6: 0 | AI6: Ad Council/2025/Dig/Pro-bono/2Q26/OneFox | AJ6: 92762823 | AK6: P2+ | AN6: Nicholas Vara | AO6: Guaranteed | AP6: LFV - 1F - Tubi - Pre/Mid - ROS - DT/MB/CTV - FW - SXD | AQ6: 121448 | AR6: 46203 | AS6: 46113 | AT6: 46203 | AU6: Direct LFV | AW6: 46208.537
A7: AEGIS INNOV8 LLC | B7: 11309 | C7: 8106 | D7: HEINEKEN | E7: HEINEKEN- Deportes - Digital - UF 2025/26- 2Q26 | F7: 264662 | G7: Heineken - Deportes - ROS - A21-54 - Upfront 25/26 - 2Q'26 | H7: 572919 | I7: Heineken - Deportes - DIO - SFV - FSEN - Pre - ROS - DT/MB/CTV - non-CoV | J7: 94782838 | K7: FSEN | L7: Flat Rate | M7: 27.92 | N7: Bill on Contract | O7: 53006 | P7: 1479.94 | S7: =IF(ISBLANK(R7)," ",ROUND(R7*(IF(ISBLANK(Q7),(M7/1000),(Q7/1000))),2)) | T7: =IF(IF(COUNTIF(H$2:$H7,H7)=1,1,"")=1,SUMIF($H$2:$H$7997,H7,$S$2:$S$7997),"") -> 0 | W7: 325960 | X7: 325960 | Y7: 133244 | Z7: 133244 | AA7: 1 | AB7: 0.40877502 | AC7: 0 | AD7: 0 | AE7: Bill on Contract - Straightline | AF7: 1479.94 | AG7: 159083 | AH7: 4441.6 | AI7: HEINEKEN- Deportes - Digital - UF 2025/26- 2Q26 | AJ7: 92798069 | AK7: P21-54 | AL7: O-DNH1JO | AN7: Mike Maresca | AO7: Guaranteed | AP7: DIO - SFV - FSEN - Pre - ROS - DT/MB/CTV - non-CoV | AQ7: 121258 | AR7: 46203 | AS7: 46113 | AT7: 46203 | AU7: Direct SFV | AW7: 46208.537
A8: AEGIS INNOV8 LLC | B8: 11309 | C8: 8106 | D8: HEINEKEN | E8: HEINEKEN- Deportes - Digital - UF 2025/26- 2Q26 | F8: 264662 | G8: Heineken - Deportes - ROS - A21-54 - Upfront 25/26 - 2Q'26 | H8: 572919 | I8: Heineken - Deportes - LFV - FSLS - Pre/Mid - A21-54 - ROS - DT/MB/CTV - 2Q'26 | J8: 92798072 | K8: FOX Sports Streaming | L8: CPM | M8: 27.92 | N8: 3P CoView Imps | O8: 8570 | P8: 186.06 | S8: =IF(ISBLANK(R8)," ",ROUND(R8*(IF(ISBLANK(Q8),(M8/1000),(Q8/1000))),2)) | T8: =IF(IF(COUNTIF(H$2:$H8,H8)=1,1,"")=1,SUMIF($H$2:$H$7997,H8,$S$2:$S$7997),"") | V8: Show Only Net; NONE | W8: 18547 | X8: 11410 | Y8: 13931 | Z8: 8570 | AA8: 1 | AB8: 0.75111878 | AC8: 0 | AD8: 0 | AE8: Bill on Contract - Straightline | AF8: 186.06 | AG8: 20000 | AH8: 558.4 | AI8: HEINEKEN- Deportes - Digital - UF 2025/26- 2Q26 | AJ8: 92798069 | AK8: P21-54 | AL8: O-DNH1JO | AN8: Mike Maresca | AO8: Guaranteed | AP8: LFV - FSLS - Pre/Mid - ROS - DT/MB/CTV | AQ8: 121258 | AR8: 46203 | AS8: 46113 | AT8: 46203 | AU8: Direct LFV | AW8: 46208.537
A9: AEGIS INNOV8 LLC | B9: 11309 | C9: 8106 | D9: HEINEKEN | E9: Heineken/2Q-3Q'26 Scatter/Digital/MWC | F9: 270111 | G9: Heineken - Run of World Cup Video - AAT 21+ - Package | H9: 590783 | I9: Heineken - DIO - LFV - TUB - Pre/Mid - MWC - AAT 21+ - DT/MB/CTV | J9: 94404208 | K9: Fox Sold Tubi | L9: CPM | M9: 40 | N9: 3P Audience Target | O9: 2037014 | P9: 81480.56 | S9: =IF(ISBLANK(R9)," ",ROUND(R9*(IF(ISBLANK(Q9),(M9/1000),(Q9/1000))),2)) | T9: =IF(IF(COUNTIF(H$2:$H9,H9)=1,1,"")=1,SUMIF($H$2:$H$7997,H9,$S$2:$S$7997),"") -> 0 | W9: 2037014 | X9: 2037014 | Y9: 0 | Z9: 0 | AA9: 1 | AB9: 0 | AC9: 0 | AD9: 0 | AE9: Bill on Actuals - 3rd Party Performance | AF9: 47629.22 | AG9: 3062500 | AH9: 122500 | AI9: Heineken/2Q-3Q'26 Scatter/Digital/MWC | AJ9: 94404205 | AK9: Audience Target | AL9: O-D3098T8 | AN9: Mike Maresca | AO9: Guaranteed | AP9: DIO - LFV - TUB - Pre/Mid - MWC - DT/MB/CTV | AQ9: 129870 | AR9: 46203 | AS9: 46174 | AT9: 46222 | AU9: Direct LFV | AW9: 46208.537
A10: AEGIS INNOV8 LLC | B10: 11309 | C10: 8106 | D10: HEINEKEN | E10: Heineken/2Q-3Q'26 Scatter/Digital/MWC | F10: 270111 | G10: Heineken - Run of World Cup Video - AAT 21+ - Package | H10: 590783 | I10: Heineken - DIO - ROV - FS - Pre/Mid - MWC - AAT 21+ - DT/MB/CTV | J10: 94404211 | K10: FOX Sports | L10: CPM | M10: 40 | N10: 3P Audience Target | O10: 890204 | P10: 35608.16 | S10: =IF(ISBLANK(R10)," ",ROUND(R10*(IF(ISBLANK(Q10),(M10/1000),(Q10/1000))),2)) | T10: =IF(IF(COUNTIF(H$2:$H10,H10)=1,1,"")=1,SUMIF($H$2:$H$7997,H10,$S$2:$S$7997),"") | W10: 890204 | X10: 890204 | Y10: 0 | Z10: 0 | AA10: 1 | AB10: 0 | AC10: 0 | AD10: 0 | AE10: Bill on Actuals - 3rd Party Performance | AF10: 20412.52 | AG10: 1312500 | AH10: 52500 | AI10: Heineken/2Q-3Q'26 Scatter/Digital/MWC | AJ10: 94404205 | AK10: Audience Target | AL10: O-D3098T8 | AN10: Mike Maresca | AO10: Guaranteed | AP10: DIO - ROV - FS - Pre/Mid - MWC - DT/MB/CTV | AQ10: 129870 | AR10: 46203 | AS10: 46174 | AT10: 46222 | AU10: Direct ROV | AW10: 46208.537
A11: AEGIS INNOV8 LLC | B11: 11309 | C11: 8106 | D11: HEINEKEN | E11: Heineken/2Q-3Q'26 Scatter/Digital/MWC | F11: 270111 | G11: Heineken - World Cup Social Sponsorship Content - Package | H11: 590855 | I11: Heineken - DIO - SOC - FOX Sports - X - MWC | J11: 590857 | K11: FOX Sports - Twitter | L11: Flat Rate | M11: 225000 | N11: Bill on Contract | O11: 0 | P11: 68877.55 | S11: =IF(ISBLANK(R11)," ",ROUND(R11*(IF(ISBLANK(Q11),(M11/1000),(Q11/1000))),2)) | T11: =IF(IF(COUNTIF(H$2:$H11,H11)=1,1,"")=1,SUMIF($H$2:$H$7997,H11,$S$2:$S$7997),"") -> 0 | W11: 0 | X11: 0 | Y11: 0 | Z11: 0 | AA11: 1 | AB11: 0 | AC11: 0 | AD11: 0 | AE11: Bill on Contract - Pro-rated | AF11: 68877.55 | AG11: 225000 | AH11: 225000 | AI11: Heineken/2Q-3Q'26 Scatter/Digital/MWC | AJ11: 270111 | AK11: P2+ | AL11: O-D3098T8 | AN11: Mike Maresca | AO11: Guaranteed | AP11: DIO - SOC - FOX Sports - X - MWC | AQ11: 129870 | AR11: 46203 | AS11: 46174 | AT11: 46222 | AU11: Social X | AW11: 46208.537
A12: APEX EXCHANGE | B12: 10564 | C12: 8880 | D12: ABBVIE | E12: AbbVie Skyrizi PS DSA1 /25-26/Digital/Scatter/Entertainment/ | F12: 264043 | G12: Abbvie Skyrizi PS DSA1 - DIO - LFV - Entertainment ROS | H12: 578383 | I12: Abbvie Skyrizi PS DSA1 - DIO - LFV - RON Ent - Pre/Mid - ROS - CTV June | J12: 92973566 | K12: RON - Ent | L12: CPM | M12: 13.6 | N12: 3P CoView Imps | O12: 4309974 | P12: 53169.23 | S12: =IF(ISBLANK(R12)," ",ROUND(R12*(IF(ISBLANK(Q12),(M12/1000),(Q12/1000))),2)) | T12: =IF(IF(COUNTIF(H$2:$H12,H12)=1,1,"")=1,SUMIF($H$2:$H$7997,H12,$S$2:$S$7997),"") -> 0 | V12: Show Only Net; NONE | W12: 3390322 | X12: 3390322 | Y12: 4309974 | Z12: 4309974 | AA12: 1 | AB12: 1.2712582 | AC12: 0 | AD12: 0 | AE12: Bill on Actuals - 3rd Party Performance | AF12: 50940.75 | AG12: 3909502 | AH12: 53169.23 | AI12: AbbVie Skyrizi PS DSA1 /25-26/Digital/Scatter/Entertainment/ | AJ12: 92973560 | AK12: P2+ | AL12: O-D2PDCUV | AN12: Carly Sartwell | AO12: Guaranteed | AP12: DIO - LFV - RON Ent - Pre/Mid - ROS - DT/MB/CTV/STB | AQ12: 123490 | AR12: 46203 | AS12: 46113 | AT12: 46203 | AU12: Direct LFV | AW12: 46208.537
A13: APEX EXCHANGE | B13: 10564 | C13: 8880 | D13: ABBVIE | E13: AbbVie Skyrizi PS DSA1 /25-26/Digital/Scatter/Entertainment/ | F13: 264043 | G13: Abbvie Skyrizi PS DSA1 - DIO - LFV - Entertainment ROS | H13: 578383 | I13: Abbvie Skyrizi PS DSA1 - DIO - LFV - RON Ent - Pre/Mid - ROS - DT/MB/TB June | J13: 92973575 | K13: RON - Ent | L13: CPM | M13: 13.6 | N13: 3P Imps | O13: 1526883 | P13: 20765.61 | S13: =IF(ISBLANK(R13)," ",ROUND(R13*(IF(ISBLANK(Q13),(M13/1000),(Q13/1000))),2)) | T13: =IF(IF(COUNTIF(H$2:$H13,H13)=1,1,"")=1,SUMIF($H$2:$H$7997,H13,$S$2:$S$7997),"") | W13: 1526883 | X13: 1526883 | Y13: 0 | Z13: 0 | AA13: 1 | AB13: 0 | AC13: 0 | AD13: 0 | AE13: Bill on Actuals - 3rd Party Performance | AF13: 28654.17 | AG13: 2199095 | AH13: 29907.69 | AI13: AbbVie Skyrizi PS DSA1 /25-26/Digital/Scatter/Entertainment/ | AJ13: 92973560 | AK13: P2+ | AL13: O-D2PDCUV | AN13: Carly Sartwell | AO13: Guaranteed | AP13: DIO - LFV - RON Ent - Pre/Mid - ROS - DT/MB/CTV/STB | AQ13: 123490 | AR13: 46203 | AS13: 46113 | AT13: 46203 | AU13: Direct LFV | AW13: 46208.537
A14: APEX EXCHANGE | B14: 10564 | C14: 7472 | D14: PARAMOUNT PICTURES | E14: Paramount Pictures - Jackass 5/Digital/Satter/2Q26 | F14: 270352 | G14: APEX - Paramount Pictures - Jackass 5 - Entertainment ROS - AAT M18-34 - 2Q'26 Package | H14: 591418 | I14: APEX - Paramount Pictures - DIO - LFV - RON Ent - Pre/Mid - ROS - DT/MB/CTV/STB - AAT M18-34 - Jackass 5 - 2Q'26 | J14: 94320519 | K14: RON - Ent | L14: CPM | M14: 20 | N14: 3P Audience Target | O14: 3041031 | P14: 60000 | S14: =IF(ISBLANK(R14)," ",ROUND(R14*(IF(ISBLANK(Q14),(M14/1000),(Q14/1000))),2)) | T14: =IF(IF(COUNTIF(H$2:$H14,H14)=1,1,"")=1,SUMIF($H$2:$H$7997,H14,$S$2:$S$7997),"") -> 0 | V14: Show Only Net; NONE | W14: 3041031 | X14: 3041031 | Y14: 0 | Z14: 0 | AA14: 1 | AB14: 0 | AC14: 0 | AD14: 0 | AE14: Bill on Actuals - 3rd Party Performance | AF14: 60000 | AG14: 3000000 | AH14: 60000 | AI14: Paramount Pictures - Jackass 5/Digital/Satter/2Q26 | AJ14: 94320445 | AK14: Audience Target | AL14: O-D30JBH2 | AN14: Jeanne Feeley | AO14: Guaranteed | AP14: DIO - LFV - RON Ent - Pre/Mid - ROS - DT/MB/CTV/STB | AQ14: 129661 | AR14: 46203 | AS14: 46174 | AT14: 46201 | AU14: Direct LFV | AW14: 46208.537
A15: APEX EXCHANGE | B15: 10564 | C15: 7472 | D15: PARAMOUNT PICTURES | E15: Scary Movie/Digital/Scatter/2Q26 | F15: 269597 | G15: APEX - Paramount Pictures - Scary Movie - Entertainment ROS - AAT A18-34 - 2Q'26 Package | H15: 588711 | I15: APEX - Scary Movie - DIO - LFV - RON Ent - Pre/Mid - ROS - DT/MB/CTV/STB - AAT 18-34 - 2Q'26 | J15: 93993815 | K15: RON - Ent | L15: CPM | M15: 20 | N15: 3P Audience Target | O15: 2321592 | P15: 46431.84 | S15: =IF(ISBLANK(R15)," ",ROUND(R15*(IF(ISBLANK(Q15),(M15/1000),(Q15/1000))),2)) | T15: =IF(IF(COUNTIF(H$2:$H15,H15)=1,1,"")=1,SUMIF($H$2:$H$7997,H15,$S$2:$S$7997),"") -> 0 | V15: Show Only Net; NONE | W15: 698080 | X15: 2321592 | Y15: 0 | Z15: 0 | AA15: 1 | AB15: 0 | AC15: 0 | AD15: 0 | AE15: Bill on Actuals - 3rd Party Performance | AF15: 13568.16 | AG15: 3000000 | AH15: 60000 | AI15: Scary Movie/Digital/Scatter/2Q26 | AJ15: 93993360 | AK15: Audience Target | AL15: O-D2V5ENF-R0 | AN15: Jeanne Feeley | AO15: Guaranteed | AP15: DIO - LFV - RON Ent - Pre/Mid - ROS - DT/MB/CTV/STB | AQ15: 128349 | AR15: 46203 | AS15: 46155 | AT15: 46180 | AU15: Direct LFV | AW15: 46208.537
A16: BLISS POINT MEDIA | B16: 10966 | C16: 5472 | D16: ALBERT | E16: Albert/25-26/2Q'26/Digital/One Fox | F16: 265792 | G16: Albert - DIO - ROV - 1F SEN - Pre/Mid - ROS - FW - SXD - 2Q'26 | H16: 591110 | I16: Albert - DIO - LFV - 1F - Tubi - Pre/Mid - ROS - DT/MB/CTV - FW - SXD - 2Q'26 | J16: 94295266 | K16: Fox Sold Tubi | L16: CPM | M16: 17 | N16: 3P Imps | O16: 45614 | P16: 750.18 | S16: =IF(ISBLANK(R16)," ",ROUND(R16*(IF(ISBLANK(Q16),(M16/1000),(Q16/1000))),2)) | T16: =IF(IF(COUNTIF(H$2:$H16,H16)=1,1,"")=1,SUMIF($H$2:$H$7997,H16,$S$2:$S$7997),"") -> 0 | W16: 45614 | X16: 45614 | Y16: 0 | Z16: 0 | AA16: 1 | AB16: 0 | AC16: 0 | AD16: 0 | AE16: Bill on Actuals - 3rd Party Performance | AF16: 304.7 | AG16: 44128 | AH16: 750.18 | AI16: Albert/25-26/2Q'26/Digital/One Fox | AJ16: 93089294 | AK16: P2+ | AL16: 43091.1 | AN16: Jon Renz | AO16: Guaranteed | AP16: DIO - LFV - 1F - Tubi - Pre/Mid - ROS - DT/MB/CTV - FW - SXD | AQ16: 129468 | AR16: 46203 | AS16: 46174 | AT16: 46180 | AU16: Direct LFV | AW16: 46208.537
A17: BLISS POINT MEDIA | B17: 10966 | C17: 5472 | D17: ALBERT | E17: Albert/25-26/2Q'26/Digital/One Fox | F17: 265792 | G17: Albert - DIO - ROV - 1F SEN - Pre/Mid - ROS - FW - SXD - 2Q'26 | H17: 591110 | I17: Albert - DIO - ROV - 1F - SEN - Pre/Mid - ROS - DT/MB/CTV - SXD - 2Q'26 | J17: 94295272 | K17: OneFOX | L17: CPM | M17: 17 | N17: 3P Imps | O17: 105965 | P17: 1749.9 | S17: =IF(ISBLANK(R17)," ",ROUND(R17*(IF(ISBLANK(Q17),(M17/1000),(Q17/1000))),2)) | T17: =IF(IF(COUNTIF(H$2:$H17,H17)=1,1,"")=1,SUMIF($H$2:$H$7997,H17,$S$2:$S$7997),"") | W17: 105965 | X17: 105965 | Y17: 0 | Z17: 0 | AA17: 1 | AB17: 0 | AC17: 0 | AD17: 0 | AE17: Bill on Actuals - 3rd Party Performance | AF17: 710.76 | AG17: 102935 | AH17: 1749.9 | AI17: Albert/25-26/2Q'26/Digital/One Fox | AJ17: 93089294 | AK17: P2+ | AL17: 43091.1 | AN17: Jon Renz | AO17: Guaranteed | AP17: DIO - ROV - 1F - SEN - Pre/Mid - ROS - DT/MB/CTV - SXD | AQ17: 129468 | AR17: 46203 | AS17: 46174 | AT17: 46180 | AU17: Direct ROV | AW17: 46208.537
A18: BLISS POINT MEDIA | B18: 10966 | C18: 5472 | D18: ALBERT | E18: Albert/25-26/2Q'26/Digital/One Fox | F18: 265792 | G18: Albert - DIO - ROV - 1F SEN - Pre/Mid - ROS - FW - SXD - 2Q'26 | H18: 591123 | I18: Albert - DIO - LFV - 1F - Tubi - Pre/Mid - ROS - DT/MB/CTV - FW - SXD - 2Q'26 | J18: 94295269 | K18: Fox Sold Tubi | L18: CPM | M18: 17 | N18: 3P Imps | O18: 45803 | P18: 750.18 | S18: =IF(ISBLANK(R18)," ",ROUND(R18*(IF(ISBLANK(Q18),(M18/1000),(Q18/1000))),2)) | T18: =IF(IF(COUNTIF(H$2:$H18,H18)=1,1,"")=1,SUMIF($H$2:$H$7997,H18,$S$2:$S$7997),"") -> 0 | W18: 45803 | X18: 45803 | Y18: 0 | Z18: 0 | AA18: 1 | AB18: 0 | AC18: 0 | AD18: 0 | AE18: Bill on Actuals - 3rd Party Performance | AF18: 357.71 | AG18: 44128 | AH18: 750.18 | AI18: Albert/25-26/2Q'26/Digital/One Fox | AJ18: 93089294 | AK18: P2+ | AL18: 43091.1 | AN18: Jon Renz | AO18: Guaranteed | AP18: DIO - LFV - 1F - Tubi - Pre/Mid - ROS - DT/MB/CTV - FW - SXD | AQ18: 129468 | AR18: 46203 | AS18: 46181 | AT18: 46187 | AU18: Direct LFV | AW18: 46208.537
A19: BLISS POINT MEDIA | B19: 10966 | C19: 5472 | D19: ALBERT | E19: Albert/25-26/2Q'26/Digital/One Fox | F19: 265792 | G19: Albert - DIO - ROV - 1F SEN - Pre/Mid - ROS - FW - SXD - 2Q'26 | H19: 591123 | I19: Albert - DIO - ROV - 1F - SEN - Pre/Mid - ROS - DT/MB/CTV - SXD - 2Q'26 | J19: 94295262 | K19: OneFOX | L19: CPM | M19: 17 | N19: 3P Imps | O19: 106238 | P19: 1749.9 | S19: =IF(ISBLANK(R19)," ",ROUND(R19*(IF(ISBLANK(Q19),(M19/1000),(Q19/1000))),2)) | T19: =IF(IF(COUNTIF(H$2:$H19,H19)=1,1,"")=1,SUMIF($H$2:$H$7997,H19,$S$2:$S$7997),"") | W19: 106238 | X19: 106238 | Y19: 0 | Z19: 0 | AA19: 1 | AB19: 0 | AC19: 0 | AD19: 0 | AE19: Bill on Actuals - 3rd Party Performance | AF19: 834.41 | AG19: 102935 | AH19: 1749.9 | AI19: Albert/25-26/2Q'26/Digital/One Fox | AJ19: 93089294 | AK19: P2+ | AL19: 43091.1 | AN19: Jon Renz | AO19: Guaranteed | AP19: DIO - ROV - 1F - SEN - Pre/Mid - ROS - DT/MB/CTV - SXD | AQ19: 129468 | AR19: 46203 | AS19: 46181 | AT19: 46187 | AU19: Direct ROV | AW19: 46208.537
A20: BLISS POINT MEDIA | B20: 10966 | C20: 5472 | D20: ALBERT | E20: Albert/25-26/2Q'26/Digital/One Fox | F20: 265792 | G20: Albert - DIO - ROV - 1F SEN - Pre/Mid - ROS - FW - SXD - 2Q'26 | H20: 591126 | I20: Albert - DIO - LFV - 1F - Tubi - Pre/Mid - ROS - DT/MB/CTV - FW - SXD - 2Q'26 | J20: 94295284 | K20: Fox Sold Tubi | L20: CPM | M20: 17 | N20: 3P Imps | O20: 46061 | P20: 750.18 | S20: =IF(ISBLANK(R20)," ",ROUND(R20*(IF(ISBLANK(Q20),(M20/1000),(Q20/1000))),2)) | T20: =IF(IF(COUNTIF(H$2:$H20,H20)=1,1,"")=1,SUMIF($H$2:$H$7997,H20,$S$2:$S$7997),"") -> 0 | W20: 46061 | X20: 46061 | Y20: 0 | Z20: 0 | AA20: 1 | AB20: 0 | AC20: 0 | AD20: 0 | AE20: Bill on Actuals - 3rd Party Performance | AF20: 375.09 | AG20: 44128 | AH20: 750.18 | AI20: Albert/25-26/2Q'26/Digital/One Fox | AJ20: 93089294 | AK20: P2+ | AL20: 43091.1 | AN20: Jon Renz | AO20: Guaranteed | AP20: DIO - LFV - 1F - Tubi - Pre/Mid - ROS - DT/MB/CTV - FW - SXD | AQ20: 129468 | AR20: 46203 | AS20: 46188 | AT20: 46194 | AU20: Direct LFV | AW20: 46208.537
A21: BLISS POINT MEDIA | B21: 10966 | C21: 5472 | D21: ALBERT | E21: Albert/25-26/2Q'26/Digital/One Fox | F21: 265792 | G21: Albert - DIO - ROV - 1F SEN - Pre/Mid - ROS - FW - SXD - 2Q'26 | H21: 591126 | I21: Albert - DIO - ROV - 1F - SEN - Pre/Mid - ROS - DT/MB/CTV - SXD - 2Q'26 | J21: 94295295 | K21: OneFOX | L21: CPM | M21: 17 | N21: 3P Imps | O21: 106022 | P21: 1749.9 | S21: =IF(ISBLANK(R21)," ",ROUND(R21*(IF(ISBLANK(Q21),(M21/1000),(Q21/1000))),2)) | T21: =IF(IF(COUNTIF(H$2:$H21,H21)=1,1,"")=1,SUMIF($H$2:$H$7997,H21,$S$2:$S$7997),"") | W21: 106022 | X21: 106022 | Y21: 0 | Z21: 0 | AA21: 1 | AB21: 0 | AC21: 0 | AD21: 0 | AE21: Bill on Actuals - 3rd Party Performance | AF21: 874.95 | AG21: 102935 | AH21: 1749.9 | AI21: Albert/25-26/2Q'26/Digital/One Fox | AJ21: 93089294 | AK21: P2+ | AL21: 43091.1 | AN21: Jon Renz | AO21: Guaranteed | AP21: DIO - ROV - 1F - SEN - Pre/Mid - ROS - DT/MB/CTV - SXD | AQ21: 129468 | AR21: 46203 | AS21: 46188 | AT21: 46194 | AU21: Direct ROV | AW21: 46208.537
A22: BLISS POINT MEDIA | B22: 10966 | C22: 5472 | D22: ALBERT | E22: Albert/25-26/2Q'26/Digital/One Fox | F22: 265792 | G22: Albert - DIO - ROV - 1F SEN - Pre/Mid - ROS - FW - SXD - 2Q'26 | H22: 591129 | I22: Albert - DIO - LFV - 1F - Tubi - Pre/Mid - ROS - DT/MB/CTV - FW - SXD - 2Q'26 | J22: 94295278 | K22: Fox Sold Tubi | L22: CPM | M22: 17 | N22: 3P Imps | O22: 45961 | P22: 750.18 | S22: =IF(ISBLANK(R22)," ",ROUND(R22*(IF(ISBLANK(Q22),(M22/1000),(Q22/1000))),2)) | T22: =IF(IF(COUNTIF(H$2:$H22,H22)=1,1,"")=1,SUMIF($H$2:$H$7997,H22,$S$2:$S$7997),"") -> 0 | W22: 45961 | X22: 45961 | Y22: 0 | Z22: 0 | AA22: 1 | AB22: 0 | AC22: 0 | AD22: 0 | AE22: Bill on Actuals - 3rd Party Performance | AF22: 375.09 | AG22: 44128 | AH22: 750.18 | AI22: Albert/25-26/2Q'26/Digital/One Fox | AJ22: 93089294 | AK22: P2+ | AL22: 43091.1 | AN22: Jon Renz | AO22: Guaranteed | AP22: DIO - LFV - 1F - Tubi - Pre/Mid - ROS - DT/MB/CTV - FW - SXD | AQ22: 129468 | AR22: 46203 | AS22: 46195 | AT22: 46201 | AU22: Direct LFV | AW22: 46208.537
A23: BLISS POINT MEDIA | B23: 10966 | C23: 5472 | D23: ALBERT | E23: Albert/25-26/2Q'26/Digital/One Fox | F23: 265792 | G23: Albert - DIO - ROV - 1F SEN - Pre/Mid - ROS - FW - SXD - 2Q'26 | H23: 591129 | I23: Albert - DIO - ROV - 1F - SEN - Pre/Mid - ROS - DT/MB/CTV - SXD - 2Q'26 | J23: 94295291 | K23: OneFOX | L23: CPM | M23: 17 | N23: 3P Imps | O23: 97068 | P23: 1650.16 | S23: =IF(ISBLANK(R23)," ",ROUND(R23*(IF(ISBLANK(Q23),(M23/1000),(Q23/1000))),2)) | T23: =IF(IF(COUNTIF(H$2:$H23,H23)=1,1,"")=1,SUMIF($H$2:$H$7997,H23,$S$2:$S$7997),"") | W23: 97068 | X23: 97068 | Y23: 0 | Z23: 0 | AA23: 1 | AB23: 0 | AC23: 0 | AD23: 0 | AE23: Bill on Actuals - 3rd Party Performance | AF23: 874.95 | AG23: 102935 | AH23: 1749.9 | AI23: Albert/25-26/2Q'26/Digital/One Fox | AJ23: 93089294 | AK23: P2+ | AL23: 43091.1 | AN23: Jon Renz | AO23: Guaranteed | AP23: DIO - ROV - 1F - SEN - Pre/Mid - ROS - DT/MB/CTV - SXD | AQ23: 129468 | AR23: 46203 | AS23: 46195 | AT23: 46201 | AU23: Direct ROV | AW23: 46208.537
A24: BLISS POINT MEDIA | B24: 10966 | C24: 19872 | D24: KALSHI INC | E24: KALSHI INC / SCATTER / DIGITAL / FY 25-26 / World Cup digital | F24: 267803 | G24: Kalshi - Run of World Cup Video - MWC 2Q3Q26 | H24: 585576 | I24: Kalshi - DIO - LFV - TUB - Pre/Mid - MWC - DT/MB/CTV | J24: 94169082 | K24: Fox Sold Tubi | L24: CPM | M24: 44 | N24: 3P Imps | O24: 7048008 | P24: 310112.35 | S24: =IF(ISBLANK(R24)," ",ROUND(R24*(IF(ISBLANK(Q24),(M24/1000),(Q24/1000))),2)) | T24: =IF(IF(COUNTIF(H$2:$H24,H24)=1,1,"")=1,SUMIF($H$2:$H$7997,H24,$S$2:$S$7997),"") -> 0 | W24: 7048008 | X24: 7048008 | Y24: 0 | Z24: 0 | AA24: 1 | AB24: 0 | AC24: 0 | AD24: 0 | AE24: Bill on Actuals - 3rd Party Performance | AF24: 155241.83 | AG24: 10698864 | AH24: 470750.02 | AI24: KALSHI INC / SCATTER / DIGITAL / FY 25-26 / World Cup digital | AJ24: 94169055 | AK24: P2+ | AL24: 43543.4 | AN24: Adam Chardavoyne | AO24: Guaranteed | AP24: DIO - LFV - TUB - Pre/Mid - MWC - DT/MB/CTV | AQ24: 128876 | AR24: 46203 | AS24: 46174 | AT24: 46222 | AU24: Direct LFV | AW24: 46208.537
A25: BLISS POINT MEDIA | B25: 10966 | C25: 19872 | D25: KALSHI INC | E25: KALSHI INC / SCATTER / DIGITAL / FY 25-26 / World Cup digital | F25: 267803 | G25: Kalshi - Run of World Cup Video - MWC 2Q3Q26 | H25: 585576 | I25: Kalshi - DIO - ROV - FS - Pre/Mid - MWC - DT/MB/CTV | J25: 94169070 | K25: FOX Sports | L25: CPM | M25: 44 | N25: 3P Imps | O25: 3074716 | P25: 135287.5 | S25: =IF(ISBLANK(R25)," ",ROUND(R25*(IF(ISBLANK(Q25),(M25/1000),(Q25/1000))),2)) | T25: =IF(IF(COUNTIF(H$2:$H25,H25)=1,1,"")=1,SUMIF($H$2:$H$7997,H25,$S$2:$S$7997),"") | W25: 3074716 | X25: 3074716 | Y25: 0 | Z25: 0 | AA25: 1 | AB25: 0 | AC25: 0 | AD25: 0 | AE25: Bill on Actuals - 3rd Party Performance | AF25: 66532.21 | AG25: 4585227 | AH25: 201749.99 | AI25: KALSHI INC / SCATTER / DIGITAL / FY 25-26 / World Cup digital | AJ25: 94169055 | AK25: P2+ | AL25: 43543.4 | AN25: Adam Chardavoyne | AO25: Guaranteed | AP25: DIO - ROV - FS - Pre/Mid - MWC - DT/MB/CTV | AQ25: 128876 | AR25: 46203 | AS25: 46174 | AT25: 46222 | AU25: Direct ROV | AW25: 46208.537
A26: BLISS POINT MEDIA | B26: 10966 | C26: 19872 | D26: KALSHI INC | E26: KALSHI INC / SCATTER / DIGITAL / FY 25-26 / World Cup digital | F26: 267803 | G26: Kalshi - Run of AllFOX Video - Soccer Fans - MWC 2Q3Q26 - AAT | H26: 585595 | I26: Kalshi - DIO - LFV - 1F - Tubi - Pre/Mid - ROS - DT/MB/CTV - FW - SXD - AAT | J26: 94169089 | K26: Fox Sold Tubi | L26: CPM | M26: 20 | N26: 3P Audience Target | O26: 2008796 | P26: 40175.92 | S26: =IF(ISBLANK(R26)," ",ROUND(R26*(IF(ISBLANK(Q26),(M26/1000),(Q26/1000))),2)) | T26: =IF(IF(COUNTIF(H$2:$H26,H26)=1,1,"")=1,SUMIF($H$2:$H$7997,H26,$S$2:$S$7997),"") -> 0 | W26: 2008796 | X26: 2008796 | Y26: 0 | Z26: 0 | AA26: 1 | AB26: 0 | AC26: 0 | AD26: 0 | AE26: Bill on Actuals - 3rd Party Performance | AF26: 18376.07 | AG26: 6337500 | AH26: 126750 | AI26: KALSHI INC / SCATTER / DIGITAL / FY 25-26 / World Cup digital | AJ26: 94169055 | AK26: Audience Target | AL26: 43543.4 | AN26: Adam Chardavoyne | AO26: Guaranteed | AP26: DIO - LFV - 1F - Tubi - Pre/Mid - ROS - DT/MB/CTV - FW - SXD | AQ26: 128876 | AR26: 46203 | AS26: 46174 | AT26: 46292 | AU26: Direct LFV | AW26: 46208.537
A27: BLISS POINT MEDIA | B27: 10966 | C27: 19872 | D27: KALSHI INC | E27: KALSHI INC / SCATTER / DIGITAL / FY 25-26 / World Cup digital | F27: 267803 | G27: Kalshi - Run of AllFOX Video - Soccer Fans - MWC 2Q3Q26 - AAT | H27: 585595 | I27: Kalshi - DIO - ROV - 1F - SEN - Pre/Mid - ROS - DT/MB/CTV - SXD - AAT | J27: 94169061 | K27: OneFOX | L27: CPM | M27: 20 | N27: 3P Audience Target | O27: 4121095 | P27: 82421.9 | S27: =IF(ISBLANK(R27)," ",ROUND(R27*(IF(ISBLANK(Q27),(M27/1000),(Q27/1000))),2)) | T27: =IF(IF(COUNTIF(H$2:$H27,H27)=1,1,"")=1,SUMIF($H$2:$H$7997,H27,$S$2:$S$7997),"") | W27: 4121095 | X27: 4121095 | Y27: 0 | Z27: 0 | AA27: 1 | AB27: 0 | AC27: 0 | AD27: 0 | AE27: Bill on Actuals - 3rd Party Performance | AF27: 42877.49 | AG27: 14787500 | AH27: 295750 | AI27: KALSHI INC / SCATTER / DIGITAL / FY 25-26 / World Cup digital | AJ27: 94169055 | AK27: Audience Target | AL27: 43543.4 | AN27: Adam Chardavoyne | AO27: Guaranteed | AP27: DIO - ROV - 1F - SEN - Pre/Mid - ROS - DT/MB/CTV - SXD | AQ27: 128876 | AR27: 46203 | AS27: 46174 | AT27: 46292 | AU27: Direct ROV | AW27: 46208.537
... A34: BLISS POINT MEDIA | B34: 10966 | C34: 17500 | D34: RAMP.COM | E34: RAMP.COM / SCATTER / DIGITAL / SPORTS / FY Q4 25-26 / | F34: 266692 | G34: RAMP - DIO - ROV - FS - Pre/Mid - ROS - DT/MB - 2Q'26 | H34: 590846 | I34: RAMP - DIO - ROV - FS - Pre/Mid - ROS - DT/MB - 2Q'26 | J34: 94264168 | K34: FOX Sports | L34: CPM | M34: 28.75 | N34: 3P Imps | O34: 760 | P34: 21.85 | S34: =IF(ISBLANK(R34)," ",ROUND(R34*(IF(ISBLANK(Q34),(M34/1000),(Q34/1000))),2)) | T34: =IF(IF(COUNTIF(H$2:$H34,H34)=1,1,"")=1,SUMIF($H$2:$H$7997,H34,$S$2:$S$7997),"") -> 0 | W34: 760 | X34: 760 | Y34: 0 | Z34: 0 | AA34: 1 | AB34: 0 | AC34: 0 | AD34: 0 | AE34: Bill on Actuals - 3rd Party Performance | AF34: 9.99 | AG34: 48696 | AH34: 1400.01 | AI34: RAMP.COM / SCATTER / DIGITAL / SPORTS / FY Q4 25-26 / | AJ34: 93031315 | AK34: P2+ | AL34: 43210.1 | AN34: Adam Chardavoyne | AO34: Guaranteed | AP34: DIO - ROV - FS - Pre/Mid - ROS - DT/MB/CTV | AQ34: 129296 | AR34: 46203 | AS34: 46195 | AT34: 46201 | AU34: Direct ROV | AW34: 46208.537
A35: BPN | B35: 11163 | C35: 7672 | D35: BRISTOL MYERS SQUIBB | E35: BMS/25-26/Upfront/Digital/ENT/CAMZYOS | F35: 259418 | G35: BMS/UF/RON/25-26/AAT/2Q'26/CAMZYOS | H35: 556247 | I35: BMS/UF/RON/25-26/AAT/P35-64/2Q'26/CAMZYOS | J35: 90410993 | K35: RON - Ent | L35: CPM | M35: 42.4 | N35: 3P Audience Target | O35: 577030 | P35: 24466.07 | S35: =IF(ISBLANK(R35)," ",ROUND(R35*(IF(ISBLANK(Q35),(M35/1000),(Q35/1000))),2)) | T35: =IF(IF(COUNTIF(H$2:$H35,H35)=1,1,"")=1,SUMIF($H$2:$H$7997,H35,$S$2:$S$7997),"") -> 0 | V35: Show Only Net; NONE | W35: 216609 | X35: 577030 | Y35: 0 | Z35: 0 | AA35: 1 | AB35: 0 | AC35: 0 | AD35: 0 | AE35: Bill on Actuals - 3rd Party Performance | AF35: 9778.25 | AG35: 1768868 | AH35: 75000 | AI35: BMS/25-26/Upfront/Digital/ENT/CAMZYOS | AJ35: 90410989 | AK35: Audience Target | AL35: O-D2DMHIP-R10 | AN35: Jeanne Feeley | AO35: Guaranteed | AP35: DIO - LFV - RON Ent - Pre/Mid - ROS - DT/MB/CTV/STB | AQ35: 108708 | AR35: 46203 | AS35: 46113 | AT35: 46203 | AU35: Direct LFV | AW35: 46208.537
A36: BPN | B36: 11163 | C36: 7672 | D36: BRISTOL MYERS SQUIBB | E36: BMS/25-26/Upfront/Digital/ENT/COBENFY | F36: 259419 | G36: BMS/UF/RON/25-26/AAT/2Q'26/COBENFY | H36: 556624 | I36: BMS/UF/RON/25-26/AAT/P18-64/2Q'26/COBENFY | J36: 90411497 | K36: RON - Ent | L36: CPM | M36: 42.4 | N36: 3P Audience Target | O36: 0 | P36: 0 | S36: =IF(ISBLANK(R36)," ",ROUND(R36*(IF(ISBLANK(Q36),(M36/1000),(Q36/1000))),2)) | T36: =IF(IF(COUNTIF(H$2:$H36,H36)=1,1,"")=1,SUMIF($H$2:$H$7997,H36,$S$2:$S$7997),"") -> 0 | V36: Show Only Net; NONE | W36: 0 | X36: 0 | Y36: 0 | Z36: 0 | AA36: 1 | AB36: 0 | AC36: 0 | AD36: 0 | AE36: Bill on Actuals - 3rd Party Performance | AF36: 0 | AG36: 682694 | AH36: 28946.23 | AI36: BMS/25-26/Upfront/Digital/ENT/COBENFY | AJ36: 259419 | AK36: Audience Target | AL36: O-D2DMHCP-R11 | AN36: Jeanne Feeley | AO36: Guaranteed | AP36: DIO - LFV - RON Ent - Pre/Mid - ROS - DT/MB/CTV/STB | AQ36: 108718 | AR36: 46203 | AS36: 46113 | AT36: 46195 | AU36: Direct LFV | AW36: 46208.537
A37: BPN | B37: 11163 | C37: 7672 | D37: BRISTOL MYERS SQUIBB | E37: BMS/25-26/Upfront/Digital/ENT/QVANTIG | F37: 259421 | G37: BMS/UF/RON/25-26/AAT/2Q'26/QVANTIG | H37: 556628 | I37: BMS/UF/RON/25-26/AAT/P50+/2Q'26/QVANTIG | J37: 90411416 | K37: RON - Ent | L37: CPM | M37: 52.25 | N37: 3P Audience Target | O37: 309362 | P37: 16164.16 | S37: =IF(ISBLANK(R37)," ",ROUND(R37*(IF(ISBLANK(Q37),(M37/1000),(Q37/1000))),2)) | T37: =IF(IF(COUNTIF(H$2:$H37,H37)=1,1,"")=1,SUMIF($H$2:$H$7997,H37,$S$2:$S$7997),"") -> 0 | V37: Show Only Net; NONE | W37: 94262 | X37: 309362 | Y37: 0 | Z37: 0 | AA37: 1 | AB37: 0 | AC37: 0 | AD37: 0 | AE37: Bill on Actuals - 3rd Party Performance | AF37: 0.05 | AG37: 956938 | AH37: 50000.01 | AI37: BMS/25-26/Upfront/Digital/ENT/QVANTIG | AJ37: 90411410 | AK37: Audience Target | AL37: O-D2DMHIP-R10 | AN37: Jeanne Feeley | AO37: Guaranteed | AP37: DIO - LFV - RON Ent - Pre/Mid - ROS - DT/MB/CTV/STB | AQ37: 108730 | AR37: 46203 | AS37: 46113 | AT37: 46203 | AU37: Direct LFV | AW37: 46208.537
A38: BPN | B38: 11163 | C38: 7672 | D38: BRISTOL MYERS SQUIBB | E38: BMS/25-26/Upfront/Digital/Sports/CAMZYOS | F38: 259423 | G38: BMS/UF/SPORTS/D/25-26/LFV/AAT/2Q'26/CAMZYOS | H38: 556448 | I38: BMS/UF/SPORTS/D/25-26/LFV/AAT/P35-64/2Q'26/CAMZYOS/JUNE | J38: 93774048 | K38: FOX Sports Streaming | L38: CPM | M38: 59 | N38: 3P Audience Target | O38: 93597 | P38: 5522.22 | S38: =IF(ISBLANK(R38)," ",ROUND(R38*(IF(ISBLANK(Q38),(M38/1000),(Q38/1000))),2)) | T38: =IF(IF(COUNTIF(H$2:$H38,H38)=1,1,"")=1,SUMIF($H$2:$H$7997,H38,$S$2:$S$7997),"") -> 0 | W38: 93597 | X38: 93597 | Y38: 0 | Z38: 0 | AA38: 1 | AB38: 0 | AC38: 0 | AD38: 0 | AE38: Bill on Actuals - 3rd Party Performance | AF38: 1731.34 | AG38: 649532 | AH38: 38322.39 | AI38: BMS/25-26/Upfront/Digital/Sports/CAMZYOS | AJ38: 90408543 | AK38: Audience Target | AL38: O-D2G2382-R5 | AN38: Colleen Cahill | AO38: Guaranteed | AP38: DIO - LFV - FSLS - Pre/Mid - ROS - DT/MB/CTV | AQ38: 108737 | AR38: 46203 | AS38: 46113 | AT38: 46203 | AU38: Direct LFV | AW38: 46208.537
A39: BPN | B39: 11163 | C39: 7672 | D39: BRISTOL MYERS SQUIBB | E39: BMS/25-26/Upfront/Digital/Sports/COBENFY | F39: 259424 | G39: BMS/UF/SPORTS/D/25-26/LFV/AAT/2Q'26/COBENFY | H39: 556649 | I39: BMS/UF/SPORTS/D/25-26/LFV/AAT/P18-64/2Q'26/COBENFY/JUNE | J39: 93476104 | K39: FOX Sports Streaming | L39: CPM | M39: 59 | N39: 3P Audience Target | O39: 61072 | P39: 3564.13 | S39: =IF(ISBLANK(R39)," ",ROUND(R39*(IF(ISBLANK(Q39),(M39/1000),(Q39/1000))),2)) | T39: =IF(IF(COUNTIF(H$2:$H39,H39)=1,1,"")=1,SUMIF($H$2:$H$7997,H39,$S$2:$S$7997),"") -> 0 | W39: 61072 | X39: 61072 | Y39: 0 | Z39: 0 | AA39: 1 | AB39: 0 | AC39: 0 | AD39: 0 | AE39: Bill on Actuals - 3rd Party Performance | AF39: 1516.17 | AG39: 60409 | AH39: 3564.13 | AI39: BMS/25-26/Upfront/Digital/Sports/COBENFY | AJ39: 90465521 | AK39: Audience Target | AL39: O-D2G1SUF-R4 | AN39: Colleen Cahill | AO39: Guaranteed | AP39: DIO - LFV - FSLS - Pre/Mid - ROS - DT/MB/CTV | AQ39: 109443 | AR39: 46203 | AS39: 46113 | AT39: 46191 | AU39: Direct LFV | AW39: 46208.537
A40: CANVAS WORLDWIDE | B40: 11499 | C40: 4805 | D40: HYUNDAI | E40: Hyundai/Digital/Scatter/Sports/MWC/25-26 | F40: 261946 | G40: Hyundai - Run of World Cup Display - Package - 728x90, 300x250,320x50 - OMP | H40: 581295 | I40: Hyundai - DIS - FS - Display Unit - MWC - 728x90, 300x250,320x50 - OMP - JUNE | J40: 7291488921 | K40: FOX Sports | L40: CPM | M40: 10 | N40: 3P Imps | O40: 0 | P40: 0 | S40: =IF(ISBLANK(R40)," ",ROUND(R40*(IF(ISBLANK(Q40),(M40/1000),(Q40/1000))),2)) | T40: =IF(IF(COUNTIF(H$2:$H40,H40)=1,1,"")=1,SUMIF($H$2:$H$7997,H40,$S$2:$S$7997),"") -> 0 | W40: 0 | X40: 0 | Y40: 0 | Z40: 0 | AA40: 1 | AB40: 0 | AC40: 0 | AD40: 0 | AE40: Bill on Actuals - 3rd Party Performance | AF40: 15548.13 | AG40: 3672026 | AH40: 36720.26 | AI40: Hyundai/Digital/Scatter/Sports/MWC/25-26 | AJ40: 261946 | AK40: P2+ | AL40: tbd | AN40: Dylan Giordano | AO40: Guaranteed | AP40: DIS - FS - Display Unit - MWC | AQ40: 126577 | AR40: 46203 | AS40: 46174 | AT40: 46222 | AU40: Direct Display | AW40: 46208.537
A41: CANVAS WORLDWIDE | B41: 11499 | C41: 4805 | D41: HYUNDAI | E41: Hyundai/Digital/Scatter/Sports/MWC/25-26 | F41: 261946 | G41: Hyundai - World Cup Social Sponsorship Content - Package | H41: 582460 | I41: Hyundai - DIO - SOC - FOX Sports - Facebook/Instagram - MWC | J41: 582461 | K41: FOX Sports - FB-Inst | L41: Flat Rate | M41: 0.15 | N41: Bill on Contract | O41: 83333533 | P41: 12500.03 | S41: =IF(ISBLANK(R41)," ",ROUND(R41*(IF(ISBLANK(Q41),(M41/1000),(Q41/1000))),2)) | T41: =IF(IF(COUNTIF(H$2:$H41,H41)=1,1,"")=1,SUMIF($H$2:$H$7997,H41,$S$2:$S$7997),"") -> 0 | W41: 0 | X41: 0 | Y41: 0 | Z41: 0 | AA41: 1 | AB41: 0 | AC41: 0 | AD41: 0 | AE41: Bill on Contract - Straightline | AF41: 12500.03 | AG41: 333334 | AH41: 50000.1 | AI41: Hyundai/Digital/Scatter/Sports/MWC/25-26 | AJ41: 261946 | AK41: P2+ | AL41: tbd | AN41: Dylan Giordano | AO41: Guaranteed | AP41: DIO - SOC - FOX Sports - Facebook/Instagram - MWC | AQ41: 126577 | AR41: 46203 | AS41: 46174 | AT41: 46222 | AU41: Social Facebook/Instagram | AW41: 46208.537
A42: CANVAS WORLDWIDE | B42: 11499 | C42: 4805 | D42: HYUNDAI | E42: Hyundai/Digital/Scatter/Sports/MWC/25-26 | F42: 261946 | G42: Hyundai - World Cup Social Sponsorship Content - Package | H42: 582460 | I42: Hyundai - DIO - SOC - FOX Sports - TikTok - MWC | J42: 582464 | K42: FOX Sports - TikTok | L42: Flat Rate | M42: 0.15 | N42: Bill on Contract | O42: 83333533 | P42: 12500.03 | S42: =IF(ISBLANK(R42)," ",ROUND(R42*(IF(ISBLANK(Q42),(M42/1000),(Q42/1000))),2)) | T42: =IF(IF(COUNTIF(H$2:$H42,H42)=1,1,"")=1,SUMIF($H$2:$H$7997,H42,$S$2:$S$7997),"") | W42: 0 | X42: 0 | Y42: 0 | Z42: 0 | AA42: 1 | AB42: 0 | AC42: 0 | AD42: 0 | AE42: Bill on Contract - Straightline | AF42: 12500.03 | AG42: 333334 | AH42: 50000.1 | AI42: Hyundai/Digital/Scatter/Sports/MWC/25-26 | AJ42: 261946 | AK42: P2+ | AL42: tbd | AN42: Dylan Giordano | AO42: Guaranteed | AP42: DIO - SOC - FOX Sports - TikTok - MWC | AQ42: 126577 | AR42: 46203 | AS42: 46174 | AT42: 46222 | AU42: Social TikTok | AW42: 46208.537
A43: CANVAS WORLDWIDE | B43: 11499 | C43: 4805 | D43: HYUNDAI | E43: Hyundai/Digital/Scatter/Sports/MWC/25-26 | F43: 261946 | G43: Hyundai - World Cup Social Sponsorship Content - Package | H43: 582460 | I43: Hyundai - DIO - SOC - FOX Sports - Youtube - Custom Content - MWC | J43: 582463 | K43: FOX Sports | L43: Flat Rate | M43: 0.15 | N43: Bill on Contract | O43: 83333533 | P43: 12500.03 | S43: =IF(ISBLANK(R43)," ",ROUND(R43*(IF(ISBLANK(Q43),(M43/1000),(Q43/1000))),2)) | T43: =IF(IF(COUNTIF(H$2:$H43,H43)=1,1,"")=1,SUMIF($H$2:$H$7997,H43,$S$2:$S$7997),"") | W43: 0 | X43: 0 | Y43: 0 | Z43: 0 | AA43: 1 | AB43: 0 | AC43: 0 | AD43: 0 | AE43: Bill on Contract - Straightline | AF43: 12500.03 | AG43: 333334 | AH43: 50000.1 | AI43: Hyundai/Digital/Scatter/Sports/MWC/25-26 | AJ43: 261946 | AK43: P2+ | AL43: tbd | AN43: Dylan Giordano | AO43: Guaranteed | AP43: DIO - SOC - FOX Sports - Youtube - Custom Content - MWC | AQ43: 126577 | AR43: 46203 | AS43: 46174 | AT43: 46222 | AU43: Social | AW43: 46208.537
A44: CANVAS WORLDWIDE | B44: 11499 | C44: 4805 | D44: HYUNDAI | E44: Hyundai/Digital/Scatter/Sports/MWC/25-26 | F44: 261946 | G44: Hyundai - Run of World Cup Video - Package - OMP | H44: 582466 | I44: Hyundai - DIO - LFV - TUB - Pre/Mid - MWC - DT/MB/CTV - JUNE | J44: 93585697 | K44: Fox Sold Tubi | L44: CPM | M44: 40 | N44: 1P Imps | O44: 2624855 | P44: 104994.2 | S44: =IF(ISBLANK(R44)," ",ROUND(R44*(IF(ISBLANK(Q44),(M44/1000),(Q44/1000))),2)) | T44: =IF(IF(COUNTIF(H$2:$H44,H44)=1,1,"")=1,SUMIF($H$2:$H$7997,H44,$S$2:$S$7997),"") -> 0 | W44: 2624855 | X44: 2624855 | Y44: 0 | Z44: 0 | AA44: 1 | AB44: 0 | AC44: 0 | AD44: 0 | AE44: Bill on Actuals - 3rd Party Performance | AF44: 28843.55 | AG44: 2625000 | AH44: 105000 | AI44: Hyundai/Digital/Scatter/Sports/MWC/25-26 | AJ44: 93585683 | AK44: P2+ | AL44: tbd | AN44: Dylan Giordano | AO44: Guaranteed | AP44: DIO - LFV - TUB - Pre/Mid - MWC - DT/MB/CTV | AQ44: 126577 | AR44: 46203 | AS44: 46174 | AT44: 46222 | AU44: Direct LFV | AW44: 46208.537
A45: CANVAS WORLDWIDE | B45: 11499 | C45: 4805 | D45: HYUNDAI | E45: Hyundai/Digital/Scatter/Sports/MWC/25-26 | F45: 261946 | G45: Hyundai - Run of World Cup Video - Package - OMP | H45: 582466 | I45: Hyundai - DIO - ROV - FS - Pre/Mid - MWC - DT/MB/CTV - JUNE | J45: 93585700 | K45: FOX Sports | L45: CPM | M45: 40 | N45: 3P Imps | O45: 1140265 | P45: 45000 | S45: =IF(ISBLANK(R45)," ",ROUND(R45*(IF(ISBLANK(Q45),(M45/1000),(Q45/1000))),2)) | T45: =IF(IF(COUNTIF(H$2:$H45,H45)=1,1,"")=1,SUMIF($H$2:$H$7997,H45,$S$2:$S$7997),"") | W45: 1140265 | X45: 1140265 | Y45: 0 | Z45: 0 | AA45: 1 | AB45: 0 | AC45: 0 | AD45: 0 | AE45: Bill on Actuals - 3rd Party Performance | AF45: 12361.52 | AG45: 1125000 | AH45: 45000 | AI45: Hyundai/Digital/Scatter/Sports/MWC/25-26 | AJ45: 93585683 | AK45: P2+ | AL45: tbd | AN45: Dylan Giordano | AO45: Guaranteed | AP45: DIO - ROV - FS - Pre/Mid - MWC - DT/MB/CTV | AQ45: 126577 | AR45: 46203 | AS45: 46174 | AT45: 46222 | AU45: Direct ROV | AW45: 46208.537
A46: CANVAS WORLDWIDE | B46: 11499 | C46: 4805 | D46: HYUNDAI | E46: Hyundai/Digital/Scatter/Sports/MWC/25-26 | F46: 261946 | G46: Hyundai - Run of FOX Sports Display - Package - 728x90, 300x250,320x50, 300x600 - OMP | H46: 582471 | I46: Hyundai - DIS - FS - Display Unit - ROS - 728x90, 300x250,320x50, 300x600 - OMP - JUNE | J46: 7293780886 | K46: FOX Sports | L46: CPM | M46: 5 | N46: 3P Imps | O46: 0 | P46: 0 | S46: =IF(ISBLANK(R46)," ",ROUND(R46*(IF(ISBLANK(Q46),(M46/1000),(Q46/1000))),2)) | T46: =IF(IF(COUNTIF(H$2:$H46,H46)=1,1,"")=1,SUMIF($H$2:$H$7997,H46,$S$2:$S$7997),"") -> 0 | W46: 0 | X46: 0 | Y46: 0 | Z46: 0 | AA46: 1 | AB46: 0 | AC46: 0 | AD46: 0 | AE46: Bill on Actuals - 3rd Party Performance | AF46: 26860.94 | AG46: 13000000 | AH46: 65000 | AI46: Hyundai/Digital/Scatter/Sports/MWC/25-26 | AJ46: 261946 | AK46: P2+ | AL46: tbd | AN46: Dylan Giordano | AO46: Guaranteed | AP46: DIS - FS - Display Unit - ROS | AQ46: 126577 | AR46: 46203 | AS46: 46174 | AT46: 46234 | AU46: Direct Display | AW46: 46208.537
...

Sheet AOS Pivot
A3: Row Labels | B3: Sum of Net Invoice Amount
A4: 250383 | B4: 0
A5: 250390 | B5: 0
A6: 250528 | B6: 0
A7: 251184 | B7: 0
A8: 251751 | B8: 0
A9: 251886 | B9: 6741.12
A10: 252064 | B10: 0
A11: 252135 | B11: 0
A12: 252293 | B12: 0
A13: 252314 | B13: 0
A14: 252340 | B14: 30427.135
A15: 252528 | B15: 0
... A231: 272782 | B231: 0
A232: Grand Total | B232: 56204191

Sheet AOS Pre
A1: Agency MDM ID | B1: Primary Advertiser Name | C1: Advertiser MDM ID | D1: Deal Name | E1: Deal ID | F1: Package Name | G1: Package ID | H1: Line Item ID | I1: Line Item Name | J1: Line Item Start Date | K1: Line Item End Date | L1: Billable Third Party Server | M1: Line Item Cost Method | N1: Net Line Item Unit Cost | O1: Line Item Quantity | P1: Net Line Item Cost | Q1: Unit Type | R1: Invoice Schedule - Suggested Amount Terms | S1: Invoice Schedule - Suggested Invoice Units | T1: Invoice Schedule - Suggested Invoice Amount | U1: Actual Invoice Units Term Used | V1: Adjusted Invoice Units | W1: Actual Net Invoice Amount Term Source | X1: Adjusted Net Invoice Amount | Y1: Net Invoice Amount | Z1: Gross Invoice Amount | AA1: Primary Performance | AB1: Third Party Performance | AC1: Order Start Date | AD1: Order End Date | AE1: Account Manager | AF1: Invoice Status | AG1: Billing Period Name | AH1: Net Order Cost | AI1: Invoice ID | AJ1: Primary Salesperson
A2: AGC005226 | B2: AMAZON XCM | C2: ADV011498 | D2: Amazon XCM/Digital/Direct/Upfront/Entertainment/25-26/UPFTRES | E2: 250528 | F2: LFV - RON Ent - ROS - Pre/Mid - DT/MB/CTV/VOD - Package | G2: 3535 | H2: 538245 | I2: Amazon XCM - LFV - RON Entertainment - ROS - Pre/Mid - DT/MB/CTV/VOD - A1849 AAT - Package - 3Q'26 UPFTRES | J2: 46202 | K2: 46292 | L2: FOX DCM | M2: CPM | N2: 19 | O2: 39470842 | P2: 749946 | Q2: Impressions | R2: performance | S2: 0 | T2: 0 | U2: performance | V2: 0 | W2: invoice_schedule | X2: 0 | Y2: 0 | Z2: 0 | AC2: 46202 | AD2: 46292 | AE2: Erin Travers | AF2: None | AG2: JUN'26 | AH2: 749946 | AI2: 95194 | AJ2: Matthew DiToro
A3: AGC002601 | B3: WARNER BROS | C3: ADV006261 | D3: Warner Brothers/Digital/Direct/Upfront/Entertainment/25-26/UPFTRES | E3: 251184 | F3: LFV - RON Ent - ROS - Pre/Mid - DT/MB/CTV/VOD - Package | G3: 3535 | H3: 537460 | I3: CANCELLED - Warner Brothers - LFV - RON Entertainment - ROS - Pre/Mid - DT/MB/CTV/VOD - P2+ No CoV - Package - 2Q'26 UPFTRES | J3: 46149 | K3: 46201 | L3: FOX DCM | M3: CPM | N3: 0 | O3: 0 | P3: 0 | Q3: Impressions | R3: performance | S3: 0 | T3: 0 | U3: performance | V3: 0 | W3: invoice_schedule | X3: 0 | Y3: 0 | Z3: 0 | AC3: 46149 | AD3: 46201 | AE3: Kailey McGinn | AF3: None | AG3: JUN'26 | AH3: 0 | AI3: 101604 | AJ3: Matthew DiToro
A4: AGC001913 | B4: CONSTELLATION BRANDS | C4: ADV001091 | D4: Constellation/Modelo/25-26/Upfront/Digital/Sports/Streaming | E4: 251886 | F4: Generic Flighted Bottom Up Package | G4: 1 | H4: 534730 | I4: MODELO/UF/SPORTS/D/25-26/P2+/2Q'26 | J4: 46113 | K4: 46203 | M4: CPM | N4: 25 | O4: 4135880 | P4: 103397.01 | R4: performance | S4: 0 | T4: 0 | U4: performance | V4: 269644 | W4: invoice_schedule | X4: 6741.12 | Y4: 6741.12 | Z4: 6741.12 | AA4: 615694 | AB4: 0 | AC4: 46113 | AD4: 46203 | AE4: John Hertman | AF4: None | AG4: JUN'26 | AH4: 200000.03 | AI4: 96408 | AJ4: Colleen Cahill
A5: AGC002070 | B5: NATIONAL VISION INC | C5: ADV006329 | D5: National Vision/Digital/Upfront/ONEFOX/UF 2025/26 | E5: 252293 | F5: Generic Flighted Bottom Up Package | G5: 1 | H5: 537073 | I5: CANCELLED - National Vision - OneFOX - A25-54 - 3Q'26 Package - UPFT RES | J5: 46202 | K5: 46292 | L5: FOX DCM | M5: CPM | N5: 0 | O5: 0 | P5: 0 | Q5: Impressions | R5: performance | S5: 0 | T5: 0 | U5: performance | V5: 0 | W5: invoice_schedule | X5: 0 | Y5: 0 | Z5: 0 | AC5: 46202 | AD5: 46292 | AE5: Katie Johnson | AF5: None | AG5: JUN'26 | AH5: 0 | AI5: 95920 | AJ5: Tim Wodzisz
A6: AGC001318 | B6: KIA | C6: ADV004496 | D6: Kia/Digital/Upfront/Entertainment/UF 2025/26 - 1-3Q26 | E6: 252314 | F6: LFV - RON Ent - ROS - Pre/Mid - DT/MB/CTV/VOD - Package | G6: 3535 | H6: 537026 | I6: KIA - LFV - RON Ent - ROS - Pre/Mid - DT/MB/CTV/VOD - Package - 3Q'26 | J6: 46202 | K6: 46292 | L6: FOX DCM | M6: CPM | N6: 33.57 | O6: 7447126 | P6: 250000.02 | Q6: CoV Impressions | R6: performance | S6: 0 | T6: 0 | U6: performance | V6: 0 | W6: invoice_schedule | X6: 0 | Y6: 0 | Z6: 0 | AC6: 46202 | AD6: 46292 | AE6: Jessica Lang | AF6: None | AG6: JUN'26 | AH6: 830000.67 | AI6: 96341 | AJ6: Allison Klein
A7: AGC001035 | B7: AUDI | C7: ADV006306 | D7: Audi/Digital/Upfront/Sports/MLS/2026 | E7: 253348 | H7: 538224 | I7: Audi - LFV - FSLS - Pre - MLS - DT/MB/CTV - 100% SOV Sponsorship - 2026 | J7: 46074 | K7: 46387 | L7: FOX DCM | M7: SOV-Flat Rate | N7: 75000 | O7: 1 | P7: 75000 | Q7: n/a | R7: prorated | S7: 0 | T7: 7165.6051 | U7: prorated | V7: 0 | W7: invoice_schedule | X7: 6768.0042 | Y7: 6768.0042 | Z7: 6768.0042 | AC7: 46074 | AD7: 46387 | AE7: Kailey McGinn | AF7: None | AG7: JUN'26 | AH7: 85000.05 | AI7: 101619 | AJ7: Nicole Gamache
A8: AGC001035 | B8: AUDI | C8: ADV006306 | D8: Audi/Digital/Upfront/Sports/MLS/2026 | E8: 253348 | F8: Generic Flighted Bottom Up Package | G8: 1 | H8: 538226 | I8: Audi - LFV - ROV - FS - Pre/Mid - MLS/Soccer - DT/MB/TB/CTV - CoV - P2+ - Package - 2026 | J8: 46074 | K8: 46387 | L8: FOX DCM | M8: CPM | N8: 25.7 | O8: 389106 | P8: 10000.02 | Q8: CoV Impressions | R8: performance | S8: 0 | T8: 0 | U8: performance | V8: 16417 | W8: invoice_schedule | X8: 421.9169 | Y8: 421.9169 | Z8: 421.9169 | AA8: 17205 | AB8: 16417 | AC8: 46074 | AD8: 46387 | AE8: Kailey McGinn | AF8: None | AG8: JUN'26 | AH8: 85000.05 | AI8: 101619 | AJ8: Nicole Gamache
A9: AGC001249 | B9: US ARMY | C9: ADV000193 | D9: Army / UPFRONT / DIGITAL / SPORTS 2025/26 | E9: 254371 | F9: DIO - ROV - FS - Pre/Mid - ROS - DT/MB/CTV - Package | G9: 7968 | H9: 585268 | I9: ARMY - DIO - ROV - FS - Pre/Mid - ROS - DT/MB/CTV - 2Q'26 AAT A1849 | J9: 46136 | K9: 46201 | M9: CPM | N9: 27.97 | O9: 3166932 | P9: 88579.09 | Q9: Impressions | R9: performance | S9: 0 | T9: 0 | U9: performance | V9: 310672 | W9: invoice_schedule | X9: 8689.4958 | Y9: 8689.4958 | Z9: 8689.4958 | AA9: 327357 | AB9: 310672 | AC9: 46136 | AD9: 46201 | AE9: Anthony Gizzo | AF9: None | AG9: JUN'26 | AH9: 199999.99 | AI9: 109200 | AJ9: Adam Chardavoyne
A10: AGC001913 | B10: EGGLANDS FOOD COMPANY | C10: ADV006280 | D10: Eggland's Best/Digital/Scatter/Entertainment/2Q-3Q26 | E10: 257492 | F10: DIO - LFV - Entertainment ROS - Package | G10: 2789 | H10: 549546 | I10: EGGLAND'S BEST/D/ENT/SCATTER/RON/2-3Q'26 | J10: 46125 | K10: 46295 | L10: FOX DCM | M10: CPM | N10: 20.1 | O10: 9950249 | P10: 200000 | Q10: CoV Impressions | R10: performance | S10: 0 | T10: 0 | U10: performance | V10: 488055 | W10: invoice_schedule | X10: 9809.9055 | Y10: 9809.9055 | Z10: 9809.9055 | AA10: 502244 | AB10: 488055 | AC10: 46125 | AD10: 46295 | AE10: John Hertman | AF10: None | AG10: JUN'26 | AH10: 300000.01 | AI10: 105784 | AJ10: Jeanne Feeley
A11: AGC001913 | B11: EGGLANDS FOOD COMPANY | C11: ADV006280 | D11: Eggland's Best/Digital/Scatter/Entertainment/2Q-3Q26 | E11: 257492 | F11: DIO - LFV - Entertainment ROS - Package | G11: 2789 | H11: 549549 | I11: EGGLAND'S BEST/LFV/Amplified Absolute A Show Mix /P2+/2-3Q'26 | J11: 46162 | K11: 46177 | L11: FOX 1st Party | M11: CPM | N11: 34 | O11: 1470589 | P11: 50000.03 | Q11: CoV Impressions | R11: performance | S11: 0 | T11: 0 | U11: performance | V11: 221142 | W11: invoice_schedule | X11: 7518.83 | Y11: 7518.83 | Z11: 7518.83 | AA11: 264775 | AB11: 0 | AC11: 46162 | AD11: 46177 | AE11: John Hertman | AF11: None | AG11: JUN'26 | AH11: 300000.01 | AI11: 105784 | AJ11: Jeanne Feeley
A12: AGC001913 | B12: EGGLANDS FOOD COMPANY | C12: ADV006280 | D12: Eggland's Best/Digital/Scatter/Entertainment/2Q-3Q26 | E12: 257492 | H12: 549554 | I12: EGGLAND'S BEST/D/ENT/SCATTER/SOCIAL/@Foodclubfox | J12: 46160 | K12: 46181 | L12: FOX 1st Party | M12: SOV-Flat Rate | N12: 50000 | O12: 1 | P12: 50000 | Q12: Impressions | R12: prorated | S12: 0 | T12: 18181.818 | U12: prorated | V12: 0 | W12: invoice_schedule | X12: 18181.818 | Y12: 18181.818 | Z12: 18181.818 | AC12: 46160 | AD12: 46181 | AE12: John Hertman | AF12: None | AG12: JUN'26 | AH12: 300000.01 | AI12: 105784 | AJ12: Jeanne Feeley
A13: AGC001913 | B13: CARNIVAL CRUISE LINES | C13: ADV004004 | D13: Carnival/2026/Scatter/Digital/MWC | E13: 257594 | F13: Run of World Cup Video - Package | G13: 8005 | H13: 580820 | I13: CARNIVAL/S/SPORTS/25-26/MWC/Run of WC Video | J13: 46174 | K13: 46222 | L13: FOX DCM | M13: CPM | N13: 35 | O13: 5400000 | P13: 189000 | Q13: Impressions | R13: performance | S13: 0 | T13: 0 | U13: performance | V13: 2428121 | W13: invoice_schedule | X13: 84984.235 | Y13: 84984.235 | Z13: 84984.235 | AA13: 2429157 | AB13: 2428121 | AC13: 46174 | AD13: 46222 | AE13: John Hertman | AF13: None | AG13: JUN'26 | AH13: 600000.03 | AI13: 127378 | AJ13: Colleen Cahill
A14: AGC001913 | B14: CARNIVAL CRUISE LINES | C14: ADV004004 | D14: Carnival/2026/Scatter/Digital/MWC | E14: 257594 | F14: Run of FOX Sports Video - Package | G14: 8002 | H14: 580823 | I14: CARNIVAL/S/SPORTS/25-26/MWC/Run of FS Video | J14: 46174 | K14: 46222 | L14: FOX DCM | M14: CPM | N14: 25 | O14: 1000000 | P14: 25000 | Q14: Impressions | R14: performance | S14: 0 | T14: 0 | U14: performance | V14: 415842 | W14: invoice_schedule | X14: 10396.05 | Y14: 10396.05 | Z14: 10396.05 | AA14: 425246 | AB14: 415842 | AC14: 46174 | AD14: 46222 | AE14: John Hertman | AF14: None | AG14: JUN'26 | AH14: 600000.03 | AI14: 127378 | AJ14: Colleen Cahill
A15: AGC001913 | B15: CARNIVAL CRUISE LINES | C15: ADV004004 | D15: Carnival/2026/Scatter/Digital/MWC | E15: 257594 | F15: Run of World Cup Display - Package | G15: 8004 | H15: 580825 | I15: CARNIVAL/S/SPORTS/25-26/MWC/Run of WC Display | J15: 46174 | K15: 46222 | L15: FOX DCM | M15: CPM | N15: 6 | O15: 8333333 | P15: 50000 | Q15: Impressions | R15: performance | S15: 0 | T15: 0 | U15: performance | V15: 6061028 | W15: invoice_schedule | X15: 36366.168 | Y15: 36366.168 | Z15: 36366.168 | AA15: 6062382 | AB15: 6061028 | AC15: 46174 | AD15: 46222 | AE15: John Hertman | AF15: None | AG15: JUN'26 | AH15: 600000.03 | AI15: 127378 | AJ15: Colleen Cahill
A16: AGC001913 | B16: CARNIVAL CRUISE LINES | C16: ADV004004 | D16: Carnival/2026/Scatter/Digital/MWC | E16: 257594 | F16: World Cup Social Sponsorship Content - Package | G16: 8000 | H16: 580840 | I16: CARNIVAL/S/SPORTS/25-26/MWC/SOCIAL | J16: 46174 | K16: 46222 | L16: FOX 1st Party | M16: SOV-Flat Rate | N16: 180000 | O16: 3 | P16: 180000 | Q16: n/a | R16: prorated | S16: 2 | T16: 110204.08 | U16: prorated | V16: 2 | W16: invoice_schedule | X16: 110204.08 | Y16: 110204.08 | Z16: 110204.08 | AC16: 46174 | AD16: 46222 | AE16: John Hertman | AF16: None | AG16: JUN'26 | AH16: 600000.03 | AI16: 127378 | AJ16: Colleen Cahill
A17: AGC001913 | B17: CARNIVAL CRUISE LINES | C17: ADV004004 | D17: Carnival/2026/Scatter/Digital/MWC | E17: 257594 | F17: Run of AllFOX Video - Package | G17: 7998 | H17: 582660 | I17: CARNIVAL/S/SPORTS/25-26/ALLFOX/AAT | J17: 46174 | K17: 46222 | L17: FOX DCM | M17: CPM | N17: 21 | O17: 7380953 | P17: 155000.01 | Q17: Impressions | R17: performance | S17: 0 | T17: 0 | U17: performance | V17: 4889067 | W17: invoice_schedule | X17: 102670.41 | Y17: 102670.41 | Z17: 102670.41 | AA17: 4881622 | AB17: 4889067 | AC17: 46174 | AD17: 46222 | AE17: John Hertman | AF17: None | AG17: JUN'26 | AH17: 600000.03 | AI17: 127378 | AJ17: Colleen Cahill
A18: AGC001913 | B18: CARNIVAL CRUISE LINES | C18: ADV004004 | D18: Carnival/2026/Scatter/Digital/MWC | E18: 257594 | F18: Run of FOX Sports Display - Package | G18: 8001 | H18: 587925 | I18: CARNIVAL/S/SPORTS/25-26/Run of FOX Sports Display | J18: 46174 | K18: 46222 | L18: FOX DCM | M18: CPM | N18: 6 | O18: 166667 | P18: 1000 | Q18: Impressions | R18: performance | S18: 0 | T18: 0 | U18: performance | V18: 36331 | W18: invoice_schedule | X18: 217.986 | Y18: 217.986 | Z18: 217.986 | AA18: 36336 | AB18: 36331 | AC18: 46174 | AD18: 46222 | AE18: John Hertman | AF18: None | AG18: JUN'26 | AH18: 600000.03 | AI18: 127378 | AJ18: Colleen Cahill
A19: AGC002070 | B19: STARBUCKS | C19: ADV005074 | D19: THE STARBUCKS COMPANY/DIGITAL/SCATTER/SPORTS/MWC/2Q'26 | E19: 259125 | F19: World Cup Social Sponsorship Content - Package | G19: 8000 | H19: 582320 | I19: Starbucks - World Cup Social Sponsorship Content - 2026 MWC Package | J19: 46174 | K19: 46201 | L19: FOX 1st Party | M19: SOV-Flat Rate | N19: 99700 | O19: 3 | P19: 99700 | Q19: n/a | R19: prorated | S19: 3 | T19: 99700 | U19: prorated | V19: 3 | W19: invoice_schedule | X19: 99700 | Y19: 99700 | Z19: 99700 | AC19: 46174 | AD19: 46201 | AE19: Matthew Vellardito | AF19: None | AG19: JUN'26 | AH19: 598482 | AI19: 129149 | AJ19: Janna Goldstein
A20: AGC002070 | B20: STARBUCKS | C20: ADV005074 | D20: THE STARBUCKS COMPANY/DIGITAL/SCATTER/SPORTS/MWC/2Q'26 | E20: 259125 | F20: Run of World Cup Video - Package | G20: 8005 | H20: 582328 | I20: Starbucks - Run of World Cup Video - 2026 MWC Package | J20: 46174 | K20: 46201 | L20: FOX Innovid | M20: CPM | N20: 40 | O20: 7500000 | P20: 300000 | Q20: Impressions | R20: performance | S20: 0 | T20: 0 | U20: performance | V20: 7500000 | W20: invoice_schedule | X20: 300000 | Y20: 300000 | Z20: 300000 | AA20: 7707810 | AB20: 7723698 | AC20: 46174 | AD20: 46201 | AE20: Matthew Vellardito | AF20: None | AG20: JUN'26 | AH20: 598482 | AI20: 129149 | AJ20: Janna Goldstein
A21: AGC002070 | B21: STARBUCKS | C21: ADV005074 | D21: THE STARBUCKS COMPANY/DIGITAL/SCATTER/SPORTS/MWC/2Q'26 | E21: 259125 | F21: Run of FOX Sports Video - Package | G21: 8002 | H21: 582346 | I21: Starbucks - Run of FOX Sports Video - 2026 MWC Package | J21: 46174 | K21: 46201 | L21: FOX Innovid | M21: CPM | N21: 25 | O21: 7951280 | P21: 198782 | R21: performance | S21: 0 | T21: 0 | U21: performance | V21: 5424817 | W21: invoice_schedule | X21: 135620.42 | Y21: 135620.42 | Z21: 135620.42 | AA21: 5380998 | AB21: 5424817 | AC21: 46174 | AD21: 46201 | AE21: Matthew Vellardito | AF21: None | AG21: JUN'26 | AH21: 598482 | AI21: 129149 | AJ21: Janna Goldstein
A22: AGC002408 | B22: FCA NORTH AMERICA HOLDINGS | C22: ADV001639 | D22: FCA(Stellantis)/DIGITAL/SCATTER/SPORTS/MWC | E22: 259149 | F22: Run of World Cup Video - Package | G22: 8005 | H22: 582769 | I22: Stellantis - Run of World Cup Video + Tubi - Package 2026 | J22: 46174 | K22: 46222 | L22: FOX Innovid | M22: CPM | N22: 40 | O22: 17500000 | P22: 700000 | Q22: Impressions | R22: performance | S22: 0 | T22: 0 | U22: performance | V22: 11628821 | W22: invoice_schedule | X22: 465152.84 | Y22: 465152.84 | Z22: 465152.84 | AA22: 11607293 | AB22: 11628821 | AC22: 46174 | AD22: 46222 | AE22: Megan Sileo | AF22: None | AG22: JUN'26 | AH22: 1275000 | AI22: 126262 | AJ22: Janna Goldstein
A23: AGC002408 | B23: FCA NORTH AMERICA HOLDINGS | C23: ADV001639 | D23: FCA(Stellantis)/DIGITAL/SCATTER/SPORTS/MWC | E23: 259149 | F23: Run of AllFOX Video - Package | G23: 7998 | H23: 582772 | I23: Stellantis - Run of AllFOX Video - Package -AAT- 2026 | J23: 46174 | K23: 46222 | L23: FOX Innovid | M23: CPM | N23: 18.25 | O23: 17808220 | P23: 325000.02 | Q23: Impressions | R23: performance | S23: 0 | T23: 0 | U23: performance | V23: 12109273 | W23: invoice_schedule | X23: 220994.23 | Y23: 220994.23 | Z23: 220994.23 | AA23: 12124261 | AB23: 12109273 | AC23: 46174 | AD23: 46222 | AE23: Megan Sileo | AF23: None | AG23: JUN'26 | AH23: 1275000 | AI23: 126262 | AJ23: Janna Goldstein
A24: AGC002408 | B24: FCA NORTH AMERICA HOLDINGS | C24: ADV001639 | D24: FCA(Stellantis)/DIGITAL/SCATTER/SPORTS/MWC | E24: 259149 | F24: World Cup Social Sponsorship Content - Package | G24: 8000 | H24: 582785 | I24: Stellantis - World Cup Social Sponsorship Content - X Amplify - Package - 2026 | J24: 46174 | K24: 46222 | L24: FOX 1st Party | M24: SOV-Flat Rate | N24: 250000 | O24: 1 | P24: 250000 | Q24: n/a | R24: prorated | S24: 1 | T24: 153061.22 | U24: prorated | V24: 1 | W24: invoice_schedule | X24: 153061.22 | Y24: 153061.22 | Z24: 153061.22 | AC24: 46174 | AD24: 46222 | AE24: Megan Sileo | AF24: None | AG24: JUN'26 | AH24: 1275000 | AI24: 126262 | AJ24: Janna Goldstein
